Workbook

Sheet BCC
H1: Công ty Cổ phần Quốc tế Thương mại và Dịch vụ Việt Pháp
H2: MST: 0201307104
H3: Địa chỉ: Số 12 Lô 18D Lê Hồng Phong, P.Đằng Lâm, Q.Hải An, Hải Phòng
A7: STT | B7: STT | C7: Mã nhân viên | E7: Họ và tên | F7: Ngày vào | G7: Ngày nghỉ | H7: Bộ phận | I7: T2 | M7: T3 | Q7: T4 | U7: T5 | Y7: T6 | AC7: T7 | AG7: CN | AK7: 8 | AO7: 9 | AS7: 10 | AW7: 11 | BA7: 12 | BE7: 13 | BI7: 14 | BM7: 15 | BQ7: 16 | BU7: 17 | BY7: 18 | CC7: 19 | CG7: 20 | CK7: 21 | CO7: 22 | CS7: 23 | CW7: 24 | DA7: 25 | DE7: 26 | DI7: 27 | DM7: 28 | DQ7: 29 | DU7: 30 | DY7: 31 | EC7: Tổng hợp | EK7: Tiền ăn tăng ca | EM7: Hồ Sơ
D8: CCCD | I8: 1 | M8: 2 | Q8: 3 | U8: 4 | Y8: 5 | AC8: 6 | AG8: 7 | AK8: T2 | AO8: T3 | AS8: T4 | AW8: T5 | BA8: T6 | BE8: T7 | BI8: CN | BM8: T2 | BQ8: T3 | BU8: T4 | BY8: T5 | CC8: T6 | CG8: T7 | CK8: CN | CO8: T2 | CS8: T3 | CW8: T4 | DA8: T5 | DE8: T6 | DI8: T7 | DM8: CN | DQ8: T2 | DU8: T3 | DY8: T4 | EK8: Tăng ca 2 - 2,5 | EL8: Tăng ca 3 - 4
I9: 36000 | J9: 54000 | K9: 46800 | L9: 75600 | M9: 36000 | N9: 54000 | O9: 46800 | P9: 75600 | Q9: 36000 | R9: 54000 | S9: 46800 | T9: 75600 | U9: 36000 | V9: 54000 | W9: 46800 | X9: 75600 | Y9: 36000 | Z9: 54000 | AA9: 46800 | AB9: 75600 | AC9: 36000 | AD9: 54000 | AE9: 46800 | AF9: 75600 | AG9: 72000 | AH9: 72000 | AI9: 97200 | AJ9: 72000 | AK9: 36000 | AL9: 54000 | AM9: 46800 | AN9: 75600 | AO9: 36000 | AP9: 54000 | AQ9: 46800 | AR9: 75600 | AS9: 36000 | AT9: 54000 | AU9: 46800 | AV9: 75600 | AW9: 36000 | AX9: 54000 | AY9: 46800 | AZ9: 75600 | BA9: 36000 | BB9: 54000 | BC9: 46800 | BD9: 75600 | BE9: 36000 | BF9: 54000 | BG9: 46800 | BH9: 75600 | BI9: 72000 | BJ9: 72000 | BK9: 97200 | BL9: 72000 | BM9: 36000 | BN9: 54000 | BO9: 46800 | BP9: 75600 | BQ9: 36000 | BR9: 54000 | BS9: 46800 | BT9: 75600 | BU9: 36000 | BV9: 54000 | BW9: 46800 | BX9: 75600 | BY9: 36000 | BZ9: 54000 | CA9: 46800 | CB9: 75600 | CC9: 36000 | CD9: 54000 | CE9: 46800 | CF9: 75600 | CG9: 36000 | CH9: 54000 | CI9: 46800 | CJ9: 75600 | CK9: 72000 | CL9: 72000 | CM9: 97200 | CN9: 72000 | CO9: 36000 | CP9: 54000 | CQ9: 46800 | CR9: 75600 | CS9: 36000 | CT9: 54000 | CU9: 46800 | CV9: 75600 | CW9: 36000 | CX9: 54000 | CY9: 46800 | CZ9: 75600 | DA9: 36000 | DB9: 54000 | DC9: 46800 | DD9: 75600 | DE9: 36000 | DF9: 54000 | DG9: 46800 | DH9: 75600 | DI9: 36000 | DJ9: 54000 | DK9: 46800 | DL9: 75600 | DM9: 72000 | DN9: 72000 | DO9: 97200 | DP9: 72000 | DQ9: 36000 | DR9: 54000 | DS9: 46800 | DT9: 75600 | DU9: 36000 | DV9: 54000 | DW9: 46800 | DX9: 75600 | DY9: 36000 | DZ9: 54000 | EA9: 46800 | EB9: 75600
I10: CB N | J10: OT N | K10: CB Đ | L10: OT Đ | M10: CB N | N10: OT N | O10: CB Đ | P10: OT Đ | Q10: CB N | R10: OT N | S10: CB Đ | T10: OT Đ | U10: CB N | V10: OT N | W10: CB Đ | X10: OT Đ | Y10: CB N | Z10: OT N | AA10: CB Đ | AB10: OT Đ | AC10: CB N | AD10: OT N | AE10: CB Đ | AF10: OT Đ | AG10: CN N | AH10: OT CN N | AI10: CN Đ | AJ10: OT CN Đ | AK10: CB N | AL10: OT N | AM10: CB Đ | AN10: OT Đ | AO10: CB N | AP10: OT N | AQ10: CB Đ | AR10: OT Đ | AS10: CB N | AT10: OT N | AU10: CB Đ | AV10: OT Đ | AW10: CB N | AX10: OT N | AY10: CB Đ | AZ10: OT Đ | BA10: CB N | BB10: OT N | BC10: CB Đ | BD10: OT Đ | BE10: CB N | BF10: OT N | BG10: CB Đ | BH10: OT Đ | BI10: CN N | BJ10: OT CN N | BK10: CN Đ | BL10: OT CN Đ | BM10: CB N | BN10: OT N | BO10: CB Đ | BP10: OT Đ | BQ10: CB N | BR10: OT N | BS10: CB Đ | BT10: OT Đ | BU10: CB N | BV10: OT N | BW10: CB Đ | BX10: OT Đ | BY10: CB N | BZ10: OT N | CA10: CB Đ | CB10: OT Đ | CC10: CB N | CD10: OT N | CE10: CB Đ | CF10: OT Đ | CG10: CB N | CH10: OT N | CI10: CB Đ | CJ10: OT Đ | CK10: CN N | CL10: OT CN N | CM10: CN Đ | CN10: OT CN Đ | CO10: CB N | CP10: OT N | CQ10: CB Đ | CR10: OT Đ | CS10: CB N | CT10: OT N | CU10: CB Đ | CV10: OT Đ | CW10: CB N | CX10: OT N | CY10: CB Đ | CZ10: OT Đ | DA10: CB N | DB10: OT N | DC10: CB Đ | DD10: OT Đ | DE10: CB N | DF10: OT N | DG10: CB Đ | DH10: OT Đ | DI10: CB N | DJ10: OT N | DK10: CB Đ | DL10: OT Đ | DM10: CN N | DN10: OT CN N | DO10: CN Đ | DP10: OT CN Đ | DQ10: CB N | DR10: OT N | DS10: CB Đ | DT10: OT Đ | DU10: CB N | DV10: OT N | DW10: CB Đ | DX10: OT Đ | DY10: CB N | DZ10: OT N | EA10: CB Đ | EB10: OT Đ | EC10: CB N | ED10: OT N | EE10: CB Đ | EF10: OT Đ | EG10: CN N | EH10: OT CN N | EI10: CN Đ | EJ10: OT CN Đ | EK10: 12000 | EL10: 20000
B11: 03 | C11: LV001114 | D11: 031206017692 | E11: Phạm Trần Nhất Long | F11: 46169 | H11: Đóng gói | I11: 8 | J11: 3 | M11: 8 | N11: 3 | Q11: 8 | R11: 3 | U11: 7.5 | V11: 3 | Y11: 8 | Z11: 3 | AC11: 8 | AD11: 3 | EC11: =SUMIF($I$10:$EB$10,$EC$10,I11:EB11) -> 47.5 | ED11: =SUMIF($I$10:$EB$10,$ED$10,I11:EB11) -> 18 | EE11: =SUMIF($I$10:$EB$10,$EE$10,I11:EB11) -> 0 | EF11: =SUMIF($I$10:$EB$10,$EF$10,I11:EB11) -> 0 | EG11: =SUMIF($I$10:$EB$10,EG$10,$I11:$EB11) -> 0 | EH11: =SUMIF($I$10:$EB$10,EH$10,$I11:$EB11) -> 0 | EI11: =SUMIF($I$10:$EB$10,EI$10,$I11:$EB11) -> 0 | EJ11: =SUMIF($I$10:$EB$10,EJ$10,$I11:$EB11) -> 0
B12: 04 | C12: LV001116 | D12: 031205013403 | E12: Nguyễn Tuấn Quang | F12: 46169 | H12: Đóng gói | I12: 8 | J12: 3 | M12: 8 | N12: 3 | Q12: 8 | R12: 3 | U12: 8 | V12: 3 | Y12: 8 | Z12: 3 | AC12: 8 | AD12: 3 | EC12: =SUMIF($I$10:$EB$10,$EC$10,I12:EB12) -> 48 | ED12: =SUMIF($I$10:$EB$10,$ED$10,I12:EB12) -> 18 | EE12: =SUMIF($I$10:$EB$10,$EE$10,I12:EB12) -> 0 | EF12: =SUMIF($I$10:$EB$10,$EF$10,I12:EB12) -> 0 | EG12: =SUMIF($I$10:$EB$10,EG$10,$I12:$EB12) -> 0 | EH12: =SUMIF($I$10:$EB$10,EH$10,$I12:$EB12) -> 0 | EI12: =SUMIF($I$10:$EB$10,EI$10,$I12:$EB12) -> 0 | EJ12: =SUMIF($I$10:$EB$10,EJ$10,$I12:$EB12) -> 0
B13: 05 | C13: LV001111 | D13: 031204008916 | E13: Phạm Văn Khánh | F13: 46169 | H13: Kim Loại | I13: 8 | J13: 3 | M13: 8 | N13: 3 | Q13: 8 | R13: 3 | U13: 7.5 | V13: 3 | Y13: 8 | Z13: 3 | AC13: 8 | AD13: 3 | EC13: =SUMIF($I$10:$EB$10,$EC$10,I13:EB13) -> 47.5 | ED13: =SUMIF($I$10:$EB$10,$ED$10,I13:EB13) -> 18 | EE13: =SUMIF($I$10:$EB$10,$EE$10,I13:EB13) -> 0 | EF13: =SUMIF($I$10:$EB$10,$EF$10,I13:EB13) -> 0 | EG13: =SUMIF($I$10:$EB$10,EG$10,$I13:$EB13) -> 0 | EH13: =SUMIF($I$10:$EB$10,EH$10,$I13:$EB13) -> 0 | EI13: =SUMIF($I$10:$EB$10,EI$10,$I13:$EB13) -> 0 | EJ13: =SUMIF($I$10:$EB$10,EJ$10,$I13:$EB13) -> 0
B14: 07 | C14: LV001113 | D14: 031206019231 | E14: Chu Ngọc Vỹ | F14: 46169 | H14: Kim loại | I14: 8 | J14: 3 | M14: 8 | N14: 3 | Q14: 8 | R14: 3 | U14: 8 | V14: 3 | Y14: 8 | Z14: 3 | EC14: =SUMIF($I$10:$EB$10,$EC$10,I14:EB14) -> 40 | ED14: =SUMIF($I$10:$EB$10,$ED$10,I14:EB14) -> 15 | EE14: =SUMIF($I$10:$EB$10,$EE$10,I14:EB14) -> 0 | EF14: =SUMIF($I$10:$EB$10,$EF$10,I14:EB14) -> 0 | EG14: =SUMIF($I$10:$EB$10,EG$10,$I14:$EB14) -> 0 | EH14: =SUMIF($I$10:$EB$10,EH$10,$I14:$EB14) -> 0 | EI14: =SUMIF($I$10:$EB$10,EI$10,$I14:$EB14) -> 0 | EJ14: =SUMIF($I$10:$EB$10,EJ$10,$I14:$EB14) -> 0
A15: 19 | B15: 08 | C15: LV000738 | D15: 034176005982 | E15: Phạm Thị Loan | F15: 46148 | H15: Kho | I15: 8 | M15: 8 | N15: 4 | Q15: 8 | R15: 4 | U15: 8 | V15: 4 | Y15: 8 | Z15: 3 | EC15: =SUMIF($I$10:$EB$10,$EC$10,I15:EB15) -> 40 | ED15: =SUMIF($I$10:$EB$10,$ED$10,I15:EB15) -> 15 | EE15: =SUMIF($I$10:$EB$10,$EE$10,I15:EB15) -> 0 | EF15: =SUMIF($I$10:$EB$10,$EF$10,I15:EB15) -> 0 | EG15: =SUMIF($I$10:$EB$10,EG$10,$I15:$EB15) -> 0 | EH15: =SUMIF($I$10:$EB$10,EH$10,$I15:$EB15) -> 0 | EI15: =SUMIF($I$10:$EB$10,EI$10,$I15:$EB15) -> 0 | EJ15: =SUMIF($I$10:$EB$10,EJ$10,$I15:$EB15) -> 0
B16: 09 | C16: LV001097 | D16: 011305002757 | E16: Phạm Trung Nguyên | F16: 46169 | H16: Kho | I16: 8 | M16: 8 | N16: 3 | Q16: 8 | R16: 4 | U16: 8 | V16: 3 | Y16: 8 | Z16: 3 | AC16: 8 | EC16: =SUMIF($I$10:$EB$10,$EC$10,I16:EB16) -> 48 | ED16: =SUMIF($I$10:$EB$10,$ED$10,I16:EB16) -> 13 | EE16: =SUMIF($I$10:$EB$10,$EE$10,I16:EB16) -> 0 | EF16: =SUMIF($I$10:$EB$10,$EF$10,I16:EB16) -> 0 | EG16: =SUMIF($I$10:$EB$10,EG$10,$I16:$EB16) -> 0 | EH16: =SUMIF($I$10:$EB$10,EH$10,$I16:$EB16) -> 0 | EI16: =SUMIF($I$10:$EB$10,EI$10,$I16:$EB16) -> 0 | EJ16: =SUMIF($I$10:$EB$10,EJ$10,$I16:$EB16) -> 0
B17: 11 | C17: LV001105 | D17: 031204007920 | E17: Vũ Văn Việt | F17: 46169 | H17: Kho | I17: 8 | M17: 8 | N17: 3 | Q17: 8 | R17: 4 | U17: 8 | V17: 3 | Y17: 8 | Z17: 3 | AC17: 8 | EC17: =SUMIF($I$10:$EB$10,$EC$10,I17:EB17) -> 48 | ED17: =SUMIF($I$10:$EB$10,$ED$10,I17:EB17) -> 13 | EE17: =SUMIF($I$10:$EB$10,$EE$10,I17:EB17) -> 0 | EF17: =SUMIF($I$10:$EB$10,$EF$10,I17:EB17) -> 0 | EG17: =SUMIF($I$10:$EB$10,EG$10,$I17:$EB17) -> 0 | EH17: =SUMIF($I$10:$EB$10,EH$10,$I17:$EB17) -> 0 | EI17: =SUMIF($I$10:$EB$10,EI$10,$I17:$EB17) -> 0 | EJ17: =SUMIF($I$10:$EB$10,EJ$10,$I17:$EB17) -> 0
B18: 12 | C18: LV001146 | D18: 014306001095 | E18: Lò Thị Chinh | F18: 46174 | H18: Kho | I18: 8 | M18: 8 | N18: 3 | Q18: 8 | R18: 3 | U18: 8 | V18: 4 | Y18: 8 | AC18: 8 | EC18: =SUMIF($I$10:$EB$10,$EC$10,I18:EB18) -> 48 | ED18: =SUMIF($I$10:$EB$10,$ED$10,I18:EB18) -> 10 | EE18: =SUMIF($I$10:$EB$10,$EE$10,I18:EB18) -> 0 | EF18: =SUMIF($I$10:$EB$10,$EF$10,I18:EB18) -> 0 | EG18: =SUMIF($I$10:$EB$10,EG$10,$I18:$EB18) -> 0 | EH18: =SUMIF($I$10:$EB$10,EH$10,$I18:$EB18) -> 0 | EI18: =SUMIF($I$10:$EB$10,EI$10,$I18:$EB18) -> 0 | EJ18: =SUMIF($I$10:$EB$10,EJ$10,$I18:$EB18) -> 0
B19: 13 | C19: LV001147 | D19: 011204001877 | E19: Lường Văn Cường | F19: 46174 | H19: Kho | I19: 8 | M19: 8 | N19: 2 | Q19: 8 | R19: 4 | U19: 8 | V19: 3 | Y19: 8 | Z19: 3 | EC19: =SUMIF($I$10:$EB$10,$EC$10,I19:EB19) -> 40 | ED19: =SUMIF($I$10:$EB$10,$ED$10,I19:EB19) -> 12 | EE19: =SUMIF($I$10:$EB$10,$EE$10,I19:EB19) -> 0 | EF19: =SUMIF($I$10:$EB$10,$EF$10,I19:EB19) -> 0 | EG19: =SUMIF($I$10:$EB$10,EG$10,$I19:$EB19) -> 0 | EH19: =SUMIF($I$10:$EB$10,EH$10,$I19:$EB19) -> 0 | EI19: =SUMIF($I$10:$EB$10,EI$10,$I19:$EB19) -> 0 | EJ19: =SUMIF($I$10:$EB$10,EJ$10,$I19:$EB19) -> 0
A20: 6 | B20: 15 | C20: LV000103 | D20: 036203011380 | E20: Nguyễn Trung Hải | H20: Lắp ráp | I20: 8 | J20: 3 | M20: 8 | N20: 3 | Q20: 7.5 | R20: 4 | U20: 8 | V20: 4 | Y20: 8 | AC20: 8 | EC20: =SUMIF($I$10:$EB$10,$EC$10,I20:EB20) -> 47.5 | ED20: =SUMIF($I$10:$EB$10,$ED$10,I20:EB20) -> 14 | EE20: =SUMIF($I$10:$EB$10,$EE$10,I20:EB20) -> 0 | EF20: =SUMIF($I$10:$EB$10,$EF$10,I20:EB20) -> 0 | EG20: =SUMIF($I$10:$EB$10,EG$10,$I20:$EB20) -> 0 | EH20: =SUMIF($I$10:$EB$10,EH$10,$I20:$EB20) -> 0 | EI20: =SUMIF($I$10:$EB$10,EI$10,$I20:$EB20) -> 0 | EJ20: =SUMIF($I$10:$EB$10,EJ$10,$I20:$EB20) -> 0
A21: 7 | B21: 16 | C21: LV000234 | D21: 011203008736 | E21: quàng văn sơn | H21: Lắp ráp | M21: 8 | N21: 3 | Q21: 8 | R21: 3 | U21: 6 | Y21: 8 | Z21: 2 | AC21: 8 | EC21: =SUMIF($I$10:$EB$10,$EC$10,I21:EB21) -> 38 | ED21: =SUMIF($I$10:$EB$10,$ED$10,I21:EB21) -> 8 | EE21: =SUMIF($I$10:$EB$10,$EE$10,I21:EB21) -> 0 | EF21: =SUMIF($I$10:$EB$10,$EF$10,I21:EB21) -> 0 | EG21: =SUMIF($I$10:$EB$10,EG$10,$I21:$EB21) -> 0 | EH21: =SUMIF($I$10:$EB$10,EH$10,$I21:$EB21) -> 0 | EI21: =SUMIF($I$10:$EB$10,EI$10,$I21:$EB21) -> 0 | EJ21: =SUMIF($I$10:$EB$10,EJ$10,$I21:$EB21) -> 0
A22: 13 | B22: 17 | C22: LV000235 | D22: 031186011750 | E22: nguyễn thị thanh hiền | H22: Lắp ráp | I22: 8 | M22: 8 | N22: 3 | Q22: 8 | R22: 3 | U22: 8 | V22: 2 | Y22: 8 | Z22: 2 | AC22: 8 | EC22: =SUMIF($I$10:$EB$10,$EC$10,I22:EB22) -> 48 | ED22: =SUMIF($I$10:$EB$10,$ED$10,I22:EB22) -> 10 | EE22: =SUMIF($I$10:$EB$10,$EE$10,I22:EB22) -> 0 | EF22: =SUMIF($I$10:$EB$10,$EF$10,I22:EB22) -> 0 | EG22: =SUMIF($I$10:$EB$10,EG$10,$I22:$EB22) -> 0 | EH22: =SUMIF($I$10:$EB$10,EH$10,$I22:$EB22) -> 0 | EI22: =SUMIF($I$10:$EB$10,EI$10,$I22:$EB22) -> 0 | EJ22: =SUMIF($I$10:$EB$10,EJ$10,$I22:$EB22) -> 0
A23: 14 | B23: 18 | C23: LV000382 | D23: 044307009163 | E23: Đinh Thị Khánh Nhi | H23: Lắp ráp | I23: 8 | M23: 8 | N23: 3 | Q23: 8 | R23: 3 | U23: 7 | V23: 3 | Y23: 8 | Z23: 2 | AC23: 8 | EC23: =SUMIF($I$10:$EB$10,$EC$10,I23:EB23) -> 47 | ED23: =SUMIF($I$10:$EB$10,$ED$10,I23:EB23) -> 11 | EE23: =SUMIF($I$10:$EB$10,$EE$10,I23:EB23) -> 0 | EF23: =SUMIF($I$10:$EB$10,$EF$10,I23:EB23) -> 0 | EG23: =SUMIF($I$10:$EB$10,EG$10,$I23:$EB23) -> 0 | EH23: =SUMIF($I$10:$EB$10,EH$10,$I23:$EB23) -> 0 | EI23: =SUMIF($I$10:$EB$10,EI$10,$I23:$EB23) -> 0 | EJ23: =SUMIF($I$10:$EB$10,EJ$10,$I23:$EB23) -> 0
A24: 15 | B24: 19 | C24: LV000384 | D24: 031176000320 | E24: Đinh Thị Tuyến | H24: Lắp ráp | I24: 8 | M24: 8 | N24: 3 | Q24: 8 | R24: 3 | U24: 8 | V24: 2 | Y24: 8 | Z24: 2 | AC24: 8 | EC24: =SUMIF($I$10:$EB$10,$EC$10,I24:EB24) -> 48 | ED24: =SUMIF($I$10:$EB$10,$ED$10,I24:EB24) -> 10 | EE24: =SUMIF($I$10:$EB$10,$EE$10,I24:EB24) -> 0 | EF24: =SUMIF($I$10:$EB$10,$EF$10,I24:EB24) -> 0 | EG24: =SUMIF($I$10:$EB$10,EG$10,$I24:$EB24) -> 0 | EH24: =SUMIF($I$10:$EB$10,EH$10,$I24:$EB24) -> 0 | EI24: =SUMIF($I$10:$EB$10,EI$10,$I24:$EB24) -> 0 | EJ24: =SUMIF($I$10:$EB$10,EJ$10,$I24:$EB24) -> 0
A25: 20 | B25: 21 | C25: LV000741 | D25: 031177006601 | E25: Đào Thị Tâm | H25: Lắp ráp | I25: 8 | J25: 3 | M25: 8 | N25: 2.5 | Q25: 4 | U25: 8 | V25: 3 | Y25: 8 | Z25: 3 | AC25: 8 | EC25: =SUMIF($I$10:$EB$10,$EC$10,I25:EB25) -> 44 | ED25: =SUMIF($I$10:$EB$10,$ED$10,I25:EB25) -> 11.5 | EE25: =SUMIF($I$10:$EB$10,$EE$10,I25:EB25) -> 0 | EF25: =SUMIF($I$10:$EB$10,$EF$10,I25:EB25) -> 0 | EG25: =SUMIF($I$10:$EB$10,EG$10,$I25:$EB25) -> 0 | EH25: =SUMIF($I$10:$EB$10,EH$10,$I25:$EB25) -> 0 | EI25: =SUMIF($I$10:$EB$10,EI$10,$I25:$EB25) -> 0 | EJ25: =SUMIF($I$10:$EB$10,EJ$10,$I25:$EB25) -> 0
A26: 23 | B26: 22 | C26: LV000774 | D26: 038304026938 | E26: Trần Thị Ngọc Thành | H26: Lắp ráp | I26: 8 | M26: 8 | N26: 3 | Q26: 8 | R26: 3 | U26: 8 | V26: 3 | EC26: =SUMIF($I$10:$EB$10,$EC$10,I26:EB26) -> 32 | ED26: =SUMIF($I$10:$EB$10,$ED$10,I26:EB26) -> 9 | EE26: =SUMIF($I$10:$EB$10,$EE$10,I26:EB26) -> 0 | EF26: =SUMIF($I$10:$EB$10,$EF$10,I26:EB26) -> 0 | EG26: =SUMIF($I$10:$EB$10,EG$10,$I26:$EB26) -> 0 | EH26: =SUMIF($I$10:$EB$10,EH$10,$I26:$EB26) -> 0 | EI26: =SUMIF($I$10:$EB$10,EI$10,$I26:$EB26) -> 0 | EJ26: =SUMIF($I$10:$EB$10,EJ$10,$I26:$EB26) -> 0
A27: 24 | B27: 23 | C27: LV000919 | D27: 011207004509 | E27: Tòng Văn Tuấn | H27: Lắp ráp | I27: 8 | M27: 8 | Q27: 8 | R27: 3 | U27: 8 | V27: 3 | Y27: 8 | Z27: 3 | AC27: 8 | EC27: =SUMIF($I$10:$EB$10,$EC$10,I27:EB27) -> 48 | ED27: =SUMIF($I$10:$EB$10,$ED$10,I27:EB27) -> 9 | EE27: =SUMIF($I$10:$EB$10,$EE$10,I27:EB27) -> 0 | EF27: =SUMIF($I$10:$EB$10,$EF$10,I27:EB27) -> 0 | EG27: =SUMIF($I$10:$EB$10,EG$10,$I27:$EB27) -> 0 | EH27: =SUMIF($I$10:$EB$10,EH$10,$I27:$EB27) -> 0 | EI27: =SUMIF($I$10:$EB$10,EI$10,$I27:$EB27) -> 0 | EJ27: =SUMIF($I$10:$EB$10,EJ$10,$I27:$EB27) -> 0
A28: 25 | B28: 24 | C28: LV000920 | D28: 011196002961 | E28: Cà Thị Thư | H28: Lắp ráp | I28: 8 | J28: 3 | M28: 8 | N28: 3 | Q28: 8 | R28: 3 | U28: 8 | V28: 3 | Y28: 8 | Z28: 3 | AC28: 8 | EC28: =SUMIF($I$10:$EB$10,$EC$10,I28:EB28) -> 48 | ED28: =SUMIF($I$10:$EB$10,$ED$10,I28:EB28) -> 15 | EE28: =SUMIF($I$10:$EB$10,$EE$10,I28:EB28) -> 0 | EF28: =SUMIF($I$10:$EB$10,$EF$10,I28:EB28) -> 0 | EG28: =SUMIF($I$10:$EB$10,EG$10,$I28:$EB28) -> 0 | EH28: =SUMIF($I$10:$EB$10,EH$10,$I28:$EB28) -> 0 | EI28: =SUMIF($I$10:$EB$10,EI$10,$I28:$EB28) -> 0 | EJ28: =SUMIF($I$10:$EB$10,EJ$10,$I28:$EB28) -> 0
A29: 28 | B29: 25 | C29: LV000922 | D29: 011205003319 | E29: Lò Ngọc Quyền | H29: Lắp ráp | I29: 8 | J29: 3 | M29: 8 | N29: 3 | Q29: 8 | R29: 3 | U29: 8 | V29: 2 | Y29: 8 | Z29: 2 | AC29: 8 | EC29: =SUMIF($I$10:$EB$10,$EC$10,I29:EB29) -> 48 | ED29: =SUMIF($I$10:$EB$10,$ED$10,I29:EB29) -> 13 | EE29: =SUMIF($I$10:$EB$10,$EE$10,I29:EB29) -> 0 | EF29: =SUMIF($I$10:$EB$10,$EF$10,I29:EB29) -> 0 | EG29: =SUMIF($I$10:$EB$10,EG$10,$I29:$EB29) -> 0 | EH29: =SUMIF($I$10:$EB$10,EH$10,$I29:$EB29) -> 0 | EI29: =SUMIF($I$10:$EB$10,EI$10,$I29:$EB29) -> 0 | EJ29: =SUMIF($I$10:$EB$10,EJ$10,$I29:$EB29) -> 0
B30: 27 | C30: LV001012 | D30: 011304000314 | E30: Lò Thị Hoàn | H30: Lắp ráp | I30: 8 | J30: 3 | M30: 8 | N30: 3 | Q30: 8 | R30: 4 | U30: 8 | V30: 3 | Y30: 8 | Z30: 3 | AC30: 8 | EC30: =SUMIF($I$10:$EB$10,$EC$10,I30:EB30) -> 48 | ED30: =SUMIF($I$10:$EB$10,$ED$10,I30:EB30) -> 16 | EE30: =SUMIF($I$10:$EB$10,$EE$10,I30:EB30) -> 0 | EF30: =SUMIF($I$10:$EB$10,$EF$10,I30:EB30) -> 0 | EG30: =SUMIF($I$10:$EB$10,EG$10,$I30:$EB30) -> 0 | EH30: =SUMIF($I$10:$EB$10,EH$10,$I30:$EB30) -> 0 | EI30: =SUMIF($I$10:$EB$10,EI$10,$I30:$EB30) -> 0 | EJ30: =SUMIF($I$10:$EB$10,EJ$10,$I30:$EB30) -> 0
B31: 28 | C31: LV001013 | D31: 001207000263 | E31: Lường Thị Phương | H31: Lắp ráp | I31: 8 | J31: 2 | M31: 8 | N31: 3 | Q31: 8 | R31: 3 | U31: 8 | V31: 3 | Y31: 8 | Z31: 2 | AC31: 8 | EC31: =SUMIF($I$10:$EB$10,$EC$10,I31:EB31) -> 48 | ED31: =SUMIF($I$10:$EB$10,$ED$10,I31:EB31) -> 13 | EE31: =SUMIF($I$10:$EB$10,$EE$10,I31:EB31) -> 0 | EF31: =SUMIF($I$10:$EB$10,$EF$10,I31:EB31) -> 0 | EG31: =SUMIF($I$10:$EB$10,EG$10,$I31:$EB31) -> 0 | EH31: =SUMIF($I$10:$EB$10,EH$10,$I31:$EB31) -> 0 | EI31: =SUMIF($I$10:$EB$10,EI$10,$I31:$EB31) -> 0 | EJ31: =SUMIF($I$10:$EB$10,EJ$10,$I31:$EB31) -> 0
B32: 30 | C32: LV001017 | D32: 011307001003 | E32: Cà Hiền Nương | H32: Lắp ráp | I32: 8 | M32: 8 | Q32: 8 | R32: 3 | U32: 8 | Y32: 8 | Z32: 3 | AC32: 8 | EC32: =SUMIF($I$10:$EB$10,$EC$10,I32:EB32) -> 48 | ED32: =SUMIF($I$10:$EB$10,$ED$10,I32:EB32) -> 6 | EE32: =SUMIF($I$10:$EB$10,$EE$10,I32:EB32) -> 0 | EF32: =SUMIF($I$10:$EB$10,$EF$10,I32:EB32) -> 0 | EG32: =SUMIF($I$10:$EB$10,EG$10,$I32:$EB32) -> 0 | EH32: =SUMIF($I$10:$EB$10,EH$10,$I32:$EB32) -> 0 | EI32: =SUMIF($I$10:$EB$10,EI$10,$I32:$EB32) -> 0 | EJ32: =SUMIF($I$10:$EB$10,EJ$10,$I32:$EB32) -> 0
B33: 31 | C33: LV001019 | D33: 011307007037 | E33: Lò Thị Thươn | H33: Lắp ráp | I33: 8 | M33: 8 | Q33: 8 | R33: 2 | U33: 8 | V33: 3 | Y33: 8 | AC33: 8 | EC33: =SUMIF($I$10:$EB$10,$EC$10,I33:EB33) -> 48 | ED33: =SUMIF($I$10:$EB$10,$ED$10,I33:EB33) -> 5 | EE33: =SUMIF($I$10:$EB$10,$EE$10,I33:EB33) -> 0 | EF33: =SUMIF($I$10:$EB$10,$EF$10,I33:EB33) -> 0 | EG33: =SUMIF($I$10:$EB$10,EG$10,$I33:$EB33) -> 0 | EH33: =SUMIF($I$10:$EB$10,EH$10,$I33:$EB33) -> 0 | EI33: =SUMIF($I$10:$EB$10,EI$10,$I33:$EB33) -> 0 | EJ33: =SUMIF($I$10:$EB$10,EJ$10,$I33:$EB33) -> 0
B34: 32 | C34: LV001020 | D34: 011307004081 | E34: Lò Thị Dương | H34: Lắp ráp | I34: 8 | M34: 8 | N34: 2 | Q34: 8 | R34: 2 | U34: 8 | V34: 2 | Y34: 8 | Z34: 2 | AC34: 8 | EC34: =SUMIF($I$10:$EB$10,$EC$10,I34:EB34) -> 48 | ED34: =SUMIF($I$10:$EB$10,$ED$10,I34:EB34) -> 8 | EE34: =SUMIF($I$10:$EB$10,$EE$10,I34:EB34) -> 0 | EF34: =SUMIF($I$10:$EB$10,$EF$10,I34:EB34) -> 0 | EG34: =SUMIF($I$10:$EB$10,EG$10,$I34:$EB34) -> 0 | EH34: =SUMIF($I$10:$EB$10,EH$10,$I34:$EB34) -> 0 | EI34: =SUMIF($I$10:$EB$10,EI$10,$I34:$EB34) -> 0 | EJ34: =SUMIF($I$10:$EB$10,EJ$10,$I34:$EB34) -> 0
B35: 33 | C35: LV001021 | D35: 011306001243 | E35: Lường Thị Yến | H35: Lắp ráp | I35: 8 | J35: 2 | M35: 8 | N35: 3 | Q35: 8 | R35: 3 | U35: 8 | V35: 3 | Y35: 8 | Z35: 2 | AC35: 8 | EC35: =SUMIF($I$10:$EB$10,$EC$10,I35:EB35) -> 48 | ED35: =SUMIF($I$10:$EB$10,$ED$10,I35:EB35) -> 13 | EE35: =SUMIF($I$10:$EB$10,$EE$10,I35:EB35) -> 0 | EF35: =SUMIF($I$10:$EB$10,$EF$10,I35:EB35) -> 0 | EG35: =SUMIF($I$10:$EB$10,EG$10,$I35:$EB35) -> 0 | EH35: =SUMIF($I$10:$EB$10,EH$10,$I35:$EB35) -> 0 | EI35: =SUMIF($I$10:$EB$10,EI$10,$I35:$EB35) -> 0 | EJ35: =SUMIF($I$10:$EB$10,EJ$10,$I35:$EB35) -> 0
B36: 34 | C36: LV001022 | D36: 011307003149 | E36: Lò Thị Hương | H36: Lắp ráp | I36: 8 | M36: 8 | Q36: 8 | U36: 8 | Y36: 8 | AC36: 8 | EC36: =SUMIF($I$10:$EB$10,$EC$10,I36:EB36) -> 48 | ED36: =SUMIF($I$10:$EB$10,$ED$10,I36:EB36) -> 0 | EE36: =SUMIF($I$10:$EB$10,$EE$10,I36:EB36) -> 0 | EF36: =SUMIF($I$10:$EB$10,$EF$10,I36:EB36) -> 0 | EG36: =SUMIF($I$10:$EB$10,EG$10,$I36:$EB36) -> 0 | EH36: =SUMIF($I$10:$EB$10,EH$10,$I36:$EB36) -> 0 | EI36: =SUMIF($I$10:$EB$10,EI$10,$I36:$EB36) -> 0 | EJ36: =SUMIF($I$10:$EB$10,EJ$10,$I36:$EB36) -> 0
B37: 36 | C37: LV001085 | D37: 011304001955 | E37: Lường Thị Na | H37: Lắp ráp | I37: 8 | M37: 8 | N37: 3 | Q37: 8 | R37: 3 | U37: 8 | Y37: 8 | EC37: =SUMIF($I$10:$EB$10,$EC$10,I37:EB37) -> 40 | ED37: =SUMIF($I$10:$EB$10,$ED$10,I37:EB37) -> 6 | EE37: =SUMIF($I$10:$EB$10,$EE$10,I37:EB37) -> 0 | EF37: =SUMIF($I$10:$EB$10,$EF$10,I37:EB37) -> 0 | EG37: =SUMIF($I$10:$EB$10,EG$10,$I37:$EB37) -> 0 | EH37: =SUMIF($I$10:$EB$10,EH$10,$I37:$EB37) -> 0 | EI37: =SUMIF($I$10:$EB$10,EI$10,$I37:$EB37) -> 0 | EJ37: =SUMIF($I$10:$EB$10,EJ$10,$I37:$EB37) -> 0
B38: 37 | C38: LV001088 | D38: 011307003959 | E38: Lò Thị Hiến | H38: Lắp ráp | I38: 8 | J38: 4 | M38: 8 | N38: 4 | Q38: 8 | R38: 4 | U38: 8 | V38: 4 | Y38: 8 | Z38: 4 | AC38: 8 | AD38: 3 | EC38: =SUMIF($I$10:$EB$10,$EC$10,I38:EB38) -> 48 | ED38: =SUMIF($I$10:$EB$10,$ED$10,I38:EB38) -> 23 | EE38: =SUMIF($I$10:$EB$10,$EE$10,I38:EB38) -> 0 | EF38: =SUMIF($I$10:$EB$10,$EF$10,I38:EB38) -> 0 | EG38: =SUMIF($I$10:$EB$10,EG$10,$I38:$EB38) -> 0 | EH38: =SUMIF($I$10:$EB$10,EH$10,$I38:$EB38) -> 0 | EI38: =SUMIF($I$10:$EB$10,EI$10,$I38:$EB38) -> 0 | EJ38: =SUMIF($I$10:$EB$10,EJ$10,$I38:$EB38) -> 0
B39: 38 | C39: LV001091 | D39: 031303006224 | E39: Nguyễn Thị Hoài Thu | H39: Lắp ráp | I39: 8 | M39: 8 | Q39: 8 | R39: 3 | U39: 8 | Y39: 8 | AC39: 8 | EC39: =SUMIF($I$10:$EB$10,$EC$10,I39:EB39) -> 48 | ED39: =SUMIF($I$10:$EB$10,$ED$10,I39:EB39) -> 3 | EE39: =SUMIF($I$10:$EB$10,$EE$10,I39:EB39) -> 0 | EF39: =SUMIF($I$10:$EB$10,$EF$10,I39:EB39) -> 0 | EG39: =SUMIF($I$10:$EB$10,EG$10,$I39:$EB39) -> 0 | EH39: =SUMIF($I$10:$EB$10,EH$10,$I39:$EB39) -> 0 | EI39: =SUMIF($I$10:$EB$10,EI$10,$I39:$EB39) -> 0 | EJ39: =SUMIF($I$10:$EB$10,EJ$10,$I39:$EB39) -> 0
B40: 39 | C40: LV001092 | D40: 011307008571 | E40: Lường Thị Yến | H40: Lắp ráp | I40: 8 | M40: 8 | N40: 3 | Q40: 8 | R40: 4 | U40: 8 | V40: 4 | Y40: 8 | AC40: 8 | EC40: =SUMIF($I$10:$EB$10,$EC$10,I40:EB40) -> 48 | ED40: =SUMIF($I$10:$EB$10,$ED$10,I40:EB40) -> 11 | EE40: =SUMIF($I$10:$EB$10,$EE$10,I40:EB40) -> 0 | EF40: =SUMIF($I$10:$EB$10,$EF$10,I40:EB40) -> 0 | EG40: =SUMIF($I$10:$EB$10,EG$10,$I40:$EB40) -> 0 | EH40: =SUMIF($I$10:$EB$10,EH$10,$I40:$EB40) -> 0 | EI40: =SUMIF($I$10:$EB$10,EI$10,$I40:$EB40) -> 0 | EJ40: =SUMIF($I$10:$EB$10,EJ$10,$I40:$EB40) -> 0
B41: 40 | C41: LV001093 | D41: 011305003834 | E41: Vì Thị Chinh | H41: Lắp ráp | I41: 8 | M41: 8 | N41: 3 | Q41: 8 | R41: 3 | U41: 8 | Y41: 8 | Z41: 3 | AC41: 8 | EC41: =SUMIF($I$10:$EB$10,$EC$10,I41:EB41) -> 48 | ED41: =SUMIF($I$10:$EB$10,$ED$10,I41:EB41) -> 9 | EE41: =SUMIF($I$10:$EB$10,$EE$10,I41:EB41) -> 0 | EF41: =SUMIF($I$10:$EB$10,$EF$10,I41:EB41) -> 0 | EG41: =SUMIF($I$10:$EB$10,EG$10,$I41:$EB41) -> 0 | EH41: =SUMIF($I$10:$EB$10,EH$10,$I41:$EB41) -> 0 | EI41: =SUMIF($I$10:$EB$10,EI$10,$I41:$EB41) -> 0 | EJ41: =SUMIF($I$10:$EB$10,EJ$10,$I41:$EB41) -> 0
B42: 43 | C42: LV001096 | D42: 011305002757 | E42: Lò Thị Minh Thư | H42: Lắp ráp | I42: 8 | M42: 8 | N42: 2 | Q42: 8 | U42: 8 | V42: 2 | Y42: 8 | Z42: 2 | EC42: =SUMIF($I$10:$EB$10,$EC$10,I42:EB42) -> 40 | ED42: =SUMIF($I$10:$EB$10,$ED$10,I42:EB42) -> 6 | EE42: =SUMIF($I$10:$EB$10,$EE$10,I42:EB42) -> 0 | EF42: =SUMIF($I$10:$EB$10,$EF$10,I42:EB42) -> 0 | EG42: =SUMIF($I$10:$EB$10,EG$10,$I42:$EB42) -> 0 | EH42: =SUMIF($I$10:$EB$10,EH$10,$I42:$EB42) -> 0 | EI42: =SUMIF($I$10:$EB$10,EI$10,$I42:$EB42) -> 0 | EJ42: =SUMIF($I$10:$EB$10,EJ$10,$I42:$EB42) -> 0
B43: 44 | C43: LV001098 | D43: 011207001253 | E43: Lường Văn Sơn | H43: Lắp ráp | I43: 8 | M43: 8 | N43: 3 | Q43: 8 | R43: 3 | U43: 8 | V43: 3 | Y43: 7.5 | Z43: 2 | AC43: 8 | EC43: =SUMIF($I$10:$EB$10,$EC$10,I43:EB43) -> 47.5 | ED43: =SUMIF($I$10:$EB$10,$ED$10,I43:EB43) -> 11 | EE43: =SUMIF($I$10:$EB$10,$EE$10,I43:EB43) -> 0 | EF43: =SUMIF($I$10:$EB$10,$EF$10,I43:EB43) -> 0 | EG43: =SUMIF($I$10:$EB$10,EG$10,$I43:$EB43) -> 0 | EH43: =SUMIF($I$10:$EB$10,EH$10,$I43:$EB43) -> 0 | EI43: =SUMIF($I$10:$EB$10,EI$10,$I43:$EB43) -> 0 | EJ43: =SUMIF($I$10:$EB$10,EJ$10,$I43:$EB43) -> 0
...

Sheet STK
A1: DANH SÁCH STK NHÂN VIÊN DỰ ÁN
A3: STT | B3: ID | C3: Tên | D3: Stk | E3: Tên Ngân hàng | F3: Ghi chú
A4: 1 | B4: 036203011380 | C4: Nguyễn Trung Hải | D4: 9250167891011 | E4: MB | F4: =VLOOKUP(B4,BCC!$D$11:$EM$74,140,0) -> 0
A5: 2 | B5: 027202000029 | C5: Nguyễn Sỹ Hùng | D5: 296608866 | E5: MB | F5: =VLOOKUP(B5,BCC!$D$11:$EM$74,140,0) -> 0
A6: 4 | B6: 031094015626 | C6: Phạm Văn Khương | D6: 0356755184 | E6: MB | F6: =VLOOKUP(B6,BCC!$D$11:$EM$74,140,0) -> 0
A7: 7 | B7: 011203008736 | C7: Quàng Văn Sơn | D7: 0354284496 | E7: MB | F7: =VLOOKUP(B7,BCC!$D$11:$EM$74,140,0) -> 0
A8: 8 | B8: 031186011750 | C8: Nguyễn Thị Thanh Hiền | D8: 0782256973 | E8: MB | F8: =VLOOKUP(B8,BCC!$D$11:$EM$74,140,0) -> 0
A9: 9 | B9: 014190012767 | C9: Lò Thị Trường | D9: 0326769071 | E9: Abbank | F9: =VLOOKUP(B9,BCC!$D$11:$EM$74,140,0) -> 0
A10: 10 | B10: 014207002665 | C10: Lò Văn An | D10: 25011123335678 | E10: MB | F10: =VLOOKUP(B10,BCC!$D$11:$EM$74,140,0) -> 0
A11: 11 | B11: 014309004488 | C11: Lò Thị Hoạch | D11: 101882769481 | E11: Vietinbank | F11: =VLOOKUP(B11,BCC!$D$11:$EM$74,140,0) -> 0
A12: 12 | B12: 031176000320 | C12: Đinh Thị Tuyến | D12: 020054152 | E12: VIB | F12: =VLOOKUP(B12,BCC!$D$11:$EM$74,140,0) -> 0
A13: 13 | B13: 044307009163 | C13: Đinh Thị Khánh Nhi | D13: 62574823062007 | E13: MB | F13: =VLOOKUP(B13,BCC!$D$11:$EM$74,140,0) -> 0
A14: 14 | B14: 031097007895 | C14: Đồng Xuân Tuấn Vũ | D14: 101877214855 | E14: Vietinbank | F14: =VLOOKUP(B14,BCC!$D$11:$EM$74,140,0) -> 0
A15: 16 | B15: 038304026938 | C15: Trần Thị Ngọc Thành | D15: 0368324193 | E15: MB | F15: =VLOOKUP(B15,BCC!$D$11:$EM$74,140,0) -> 0
... A75: 93 | B75: 031207016981 | C75: Vũ Văn Tú | D75: 0854250922 | E75: MB | F75: =VLOOKUP(B75,BCC!$D$11:$EM$74,140,0) -> 0
F76: =VLOOKUP(B76,STK!D83:EM164,140,0) -> #N/A
F77: =VLOOKUP(B77,STK!D84:EM165,140,0) -> #N/A
